Currently Loaded Modulefiles:
 1) conda/analysis3-24.04(analysis3-unstable)  
Traceback (most recent call last):
  File "/g/data/hh5/public/apps/miniconda3/envs/analysis3-24.04/lib/python3.10/site-packages/xarray/backends/file_manager.py", line 211, in _acquire_with_cache_info
    file = self._cache[self._key]
  File "/g/data/hh5/public/apps/miniconda3/envs/analysis3-24.04/lib/python3.10/site-packages/xarray/backends/lru_cache.py", line 56, in __getitem__
    value = self._cache[key]
KeyError: [<class 'netCDF4._netCDF4.Dataset'>, ('/home/149/ab8992/topographic-NIWs/rundirs/height/height_275/archive/output000/u_10min.nc',), 'r', (('clobber', True), ('diskless', False), ('format', 'NETCDF4'), ('persist', False)), '2ede9f60-5328-4bd7-b405-61ddae9f3bb2']

During handling of the above exception, another exception occurred:

Traceback (most recent call last):
  File "/home/149/ab8992/topographic-NIWs/rundirs/height/height_275/../../../postprocess.py", line 73, in <module>
    postprocess(Path(args.expt))
  File "/home/149/ab8992/topographic-NIWs/rundirs/height/height_275/../../../postprocess.py", line 41, in postprocess
    data = xr.open_dataarray(current_output / file)
  File "/g/data/hh5/public/apps/miniconda3/envs/analysis3-24.04/lib/python3.10/site-packages/xarray/backends/api.py", line 747, in open_dataarray
    dataset = open_dataset(
  File "/g/data/hh5/public/apps/miniconda3/envs/analysis3-24.04/lib/python3.10/site-packages/xarray/backends/api.py", line 571, in open_dataset
    backend_ds = backend.open_dataset(
  File "/g/data/hh5/public/apps/miniconda3/envs/analysis3-24.04/lib/python3.10/site-packages/xarray/backends/netCDF4_.py", line 645, in open_dataset
    store = NetCDF4DataStore.open(
  File "/g/data/hh5/public/apps/miniconda3/envs/analysis3-24.04/lib/python3.10/site-packages/xarray/backends/netCDF4_.py", line 408, in open
    return cls(manager, group=group, mode=mode, lock=lock, autoclose=autoclose)
  File "/g/data/hh5/public/apps/miniconda3/envs/analysis3-24.04/lib/python3.10/site-packages/xarray/backends/netCDF4_.py", line 355, in __init__
    self.format = self.ds.data_model
  File "/g/data/hh5/public/apps/miniconda3/envs/analysis3-24.04/lib/python3.10/site-packages/xarray/backends/netCDF4_.py", line 417, in ds
    return self._acquire()
  File "/g/data/hh5/public/apps/miniconda3/envs/analysis3-24.04/lib/python3.10/site-packages/xarray/backends/netCDF4_.py", line 411, in _acquire
    with self._manager.acquire_context(needs_lock) as root:
  File "/g/data/hh5/public/apps/miniconda3/envs/analysis3-24.04/lib/python3.10/contextlib.py", line 135, in __enter__
    return next(self.gen)
  File "/g/data/hh5/public/apps/miniconda3/envs/analysis3-24.04/lib/python3.10/site-packages/xarray/backends/file_manager.py", line 199, in acquire_context
    file, cached = self._acquire_with_cache_info(needs_lock)
  File "/g/data/hh5/public/apps/miniconda3/envs/analysis3-24.04/lib/python3.10/site-packages/xarray/backends/file_manager.py", line 217, in _acquire_with_cache_info
    file = self._opener(*self._args, **kwargs)
  File "src/netCDF4/_netCDF4.pyx", line 2469, in netCDF4._netCDF4.Dataset.__init__
  File "src/netCDF4/_netCDF4.pyx", line 2028, in netCDF4._netCDF4._ensure_nc_success
FileNotFoundError: [Errno 2] No such file or directory: '/home/149/ab8992/topographic-NIWs/rundirs/height/height_275/archive/output000/u_10min.nc'
