Currently Loaded Modulefiles:
 1) conda/analysis3-24.04(analysis3-unstable)  
Traceback (most recent call last):
  File "/g/data/hh5/public/apps/miniconda3/envs/analysis3-24.04/lib/python3.10/site-packages/xarray/backends/file_manager.py", line 211, in _acquire_with_cache_info
    file = self._cache[self._key]
  File "/g/data/hh5/public/apps/miniconda3/envs/analysis3-24.04/lib/python3.10/site-packages/xarray/backends/lru_cache.py", line 56, in __getitem__
    value = self._cache[key]
KeyError: [<class 'netCDF4._netCDF4.Dataset'>, ('/home/149/ab8992/topographic-NIWs/rundirs/height/height_10/archive/output000/u_10min.nc',), 'r', (('clobber', True), ('diskless', False), ('format', 'NETCDF4'), ('persist', False)), '6a657498-4695-4262-969e-76d00eef6b18']

During handling of the above exception, another exception occurred:

Traceback (most recent call last):
  File "/home/149/ab8992/topographic-NIWs/rundirs/height/height_10/../../../postprocess.py", line 73, in <module>
    postprocess(Path(args.expt))
  File "/home/149/ab8992/topographic-NIWs/rundirs/height/height_10/../../../postprocess.py", line 41, in postprocess
    data = xr.open_dataarray(current_output / file)
  File "/g/data/hh5/public/apps/miniconda3/envs/analysis3-24.04/lib/python3.10/site-packages/xarray/backends/api.py", line 747, in open_dataarray
    dataset = open_dataset(
  File "/g/data/hh5/public/apps/miniconda3/envs/analysis3-24.04/lib/python3.10/site-packages/xarray/backends/api.py", line 571, in open_dataset
    backend_ds = backend.open_dataset(
  File "/g/data/hh5/public/apps/miniconda3/envs/analysis3-24.04/lib/python3.10/site-packages/xarray/backends/netCDF4_.py", line 645, in open_dataset
    store = NetCDF4DataStore.open(
  File "/g/data/hh5/public/apps/miniconda3/envs/analysis3-24.04/lib/python3.10/site-packages/xarray/backends/netCDF4_.py", line 408, in open
    return cls(manager, group=group, mode=mode, lock=lock, autoclose=autoclose)
  File "/g/data/hh5/public/apps/miniconda3/envs/analysis3-24.04/lib/python3.10/site-packages/xarray/backends/netCDF4_.py", line 355, in __init__
    self.format = self.ds.data_model
  File "/g/data/hh5/public/apps/miniconda3/envs/analysis3-24.04/lib/python3.10/site-packages/xarray/backends/netCDF4_.py", line 417, in ds
    return self._acquire()
  File "/g/data/hh5/public/apps/miniconda3/envs/analysis3-24.04/lib/python3.10/site-packages/xarray/backends/netCDF4_.py", line 411, in _acquire
    with self._manager.acquire_context(needs_lock) as root:
  File "/g/data/hh5/public/apps/miniconda3/envs/analysis3-24.04/lib/python3.10/contextlib.py", line 135, in __enter__
    return next(self.gen)
  File "/g/data/hh5/public/apps/miniconda3/envs/analysis3-24.04/lib/python3.10/site-packages/xarray/backends/file_manager.py", line 199, in acquire_context
    file, cached = self._acquire_with_cache_info(needs_lock)
  File "/g/data/hh5/public/apps/miniconda3/envs/analysis3-24.04/lib/python3.10/site-packages/xarray/backends/file_manager.py", line 217, in _acquire_with_cache_info
    file = self._opener(*self._args, **kwargs)
  File "src/netCDF4/_netCDF4.pyx", line 2469, in netCDF4._netCDF4.Dataset.__init__
  File "src/netCDF4/_netCDF4.pyx", line 2028, in netCDF4._netCDF4._ensure_nc_success
FileNotFoundError: [Errno 2] No such file or directory: '/home/149/ab8992/topographic-NIWs/rundirs/height/height_10/archive/output000/u_10min.nc'
2024-08-05 18:18:33,144 - distributed.worker - ERROR - Failed to communicate with scheduler during heartbeat.
Traceback (most recent call last):
  File "/g/data/hh5/public/apps/miniconda3/envs/analysis3-24.04/lib/python3.10/site-packages/distributed/comm/tcp.py", line 225, in read
    frames_nosplit_nbytes_bin = await stream.read_bytes(fmt_size)
tornado.iostream.StreamClosedError: Stream is closed

The above exception was the direct cause of the following exception:

Traceback (most recent call last):
  File "/g/data/hh5/public/apps/miniconda3/envs/analysis3-24.04/lib/python3.10/site-packages/distributed/worker.py", line 1250, in heartbeat
    response = await retry_operation(
  File "/g/data/hh5/public/apps/miniconda3/envs/analysis3-24.04/lib/python3.10/site-packages/distributed/utils_comm.py", line 459, in retry_operation
    return await retry(
  File "/g/data/hh5/public/apps/miniconda3/envs/analysis3-24.04/lib/python3.10/site-packages/distributed/utils_comm.py", line 438, in retry
    return await coro()
  File "/g/data/hh5/public/apps/miniconda3/envs/analysis3-24.04/lib/python3.10/site-packages/distributed/core.py", line 1254, in send_recv_from_rpc
    return await send_recv(comm=comm, op=key, **kwargs)
  File "/g/data/hh5/public/apps/miniconda3/envs/analysis3-24.04/lib/python3.10/site-packages/distributed/core.py", line 1013, in send_recv
    response = await comm.read(deserializers=deserializers)
  File "/g/data/hh5/public/apps/miniconda3/envs/analysis3-24.04/lib/python3.10/site-packages/distributed/comm/tcp.py", line 236, in read
    convert_stream_closed_error(self, e)
  File "/g/data/hh5/public/apps/miniconda3/envs/analysis3-24.04/lib/python3.10/site-packages/distributed/comm/tcp.py", line 142, in convert_stream_closed_error
    raise CommClosedError(f"in {obj}: {exc}") from exc
distributed.comm.core.CommClosedError: in <TCP (closed) ConnectionPool.heartbeat_worker local=tcp://127.0.0.1:50542 remote=tcp://127.0.0.1:37367>: Stream is closed
2024-08-05 18:18:33,149 - distributed.worker - ERROR - Failed to communicate with scheduler during heartbeat.
Traceback (most recent call last):
  File "/g/data/hh5/public/apps/miniconda3/envs/analysis3-24.04/lib/python3.10/site-packages/distributed/comm/tcp.py", line 225, in read
    frames_nosplit_nbytes_bin = await stream.read_bytes(fmt_size)
tornado.iostream.StreamClosedError: Stream is closed

The above exception was the direct cause of the following exception:

Traceback (most recent call last):
  File "/g/data/hh5/public/apps/miniconda3/envs/analysis3-24.04/lib/python3.10/site-packages/distributed/worker.py", line 1250, in heartbeat
    response = await retry_operation(
  File "/g/data/hh5/public/apps/miniconda3/envs/analysis3-24.04/lib/python3.10/site-packages/distributed/utils_comm.py", line 459, in retry_operation
    return await retry(
  File "/g/data/hh5/public/apps/miniconda3/envs/analysis3-24.04/lib/python3.10/site-packages/distributed/utils_comm.py", line 438, in retry
    return await coro()
  File "/g/data/hh5/public/apps/miniconda3/envs/analysis3-24.04/lib/python3.10/site-packages/distributed/core.py", line 1254, in send_recv_from_rpc
    return await send_recv(comm=comm, op=key, **kwargs)
  File "/g/data/hh5/public/apps/miniconda3/envs/analysis3-24.04/lib/python3.10/site-packages/distributed/core.py", line 1013, in send_recv
    response = await comm.read(deserializers=deserializers)
  File "/g/data/hh5/public/apps/miniconda3/envs/analysis3-24.04/lib/python3.10/site-packages/distributed/comm/tcp.py", line 236, in read
    convert_stream_closed_error(self, e)
  File "/g/data/hh5/public/apps/miniconda3/envs/analysis3-24.04/lib/python3.10/site-packages/distributed/comm/tcp.py", line 142, in convert_stream_closed_error
    raise CommClosedError(f"in {obj}: {exc}") from exc
distributed.comm.core.CommClosedError: in <TCP (closed) ConnectionPool.heartbeat_worker local=tcp://127.0.0.1:50566 remote=tcp://127.0.0.1:37367>: Stream is closed
2024-08-05 18:18:33,147 - distributed.worker - ERROR - Failed to communicate with scheduler during heartbeat.
Traceback (most recent call last):
  File "/g/data/hh5/public/apps/miniconda3/envs/analysis3-24.04/lib/python3.10/site-packages/distributed/comm/tcp.py", line 225, in read
    frames_nosplit_nbytes_bin = await stream.read_bytes(fmt_size)
tornado.iostream.StreamClosedError: Stream is closed

The above exception was the direct cause of the following exception:

Traceback (most recent call last):
  File "/g/data/hh5/public/apps/miniconda3/envs/analysis3-24.04/lib/python3.10/site-packages/distributed/worker.py", line 1250, in heartbeat
    response = await retry_operation(
  File "/g/data/hh5/public/apps/miniconda3/envs/analysis3-24.04/lib/python3.10/site-packages/distributed/utils_comm.py", line 459, in retry_operation
    return await retry(
  File "/g/data/hh5/public/apps/miniconda3/envs/analysis3-24.04/lib/python3.10/site-packages/distributed/utils_comm.py", line 438, in retry
    return await coro()
  File "/g/data/hh5/public/apps/miniconda3/envs/analysis3-24.04/lib/python3.10/site-packages/distributed/core.py", line 1254, in send_recv_from_rpc
    return await send_recv(comm=comm, op=key, **kwargs)
  File "/g/data/hh5/public/apps/miniconda3/envs/analysis3-24.04/lib/python3.10/site-packages/distributed/core.py", line 1013, in send_recv
    response = await comm.read(deserializers=deserializers)
  File "/g/data/hh5/public/apps/miniconda3/envs/analysis3-24.04/lib/python3.10/site-packages/distributed/comm/tcp.py", line 236, in read
    convert_stream_closed_error(self, e)
  File "/g/data/hh5/public/apps/miniconda3/envs/analysis3-24.04/lib/python3.10/site-packages/distributed/comm/tcp.py", line 142, in convert_stream_closed_error
    raise CommClosedError(f"in {obj}: {exc}") from exc
distributed.comm.core.CommClosedError: in <TCP (closed) ConnectionPool.heartbeat_worker local=tcp://127.0.0.1:50526 remote=tcp://127.0.0.1:37367>: Stream is closed
2024-08-05 18:18:33,147 - distributed.worker - ERROR - Failed to communicate with scheduler during heartbeat.
Traceback (most recent call last):
  File "/g/data/hh5/public/apps/miniconda3/envs/analysis3-24.04/lib/python3.10/site-packages/distributed/comm/tcp.py", line 225, in read
    frames_nosplit_nbytes_bin = await stream.read_bytes(fmt_size)
tornado.iostream.StreamClosedError: Stream is closed

The above exception was the direct cause of the following exception:

Traceback (most recent call last):
  File "/g/data/hh5/public/apps/miniconda3/envs/analysis3-24.04/lib/python3.10/site-packages/distributed/worker.py", line 1250, in heartbeat
    response = await retry_operation(
  File "/g/data/hh5/public/apps/miniconda3/envs/analysis3-24.04/lib/python3.10/site-packages/distributed/utils_comm.py", line 459, in retry_operation
    return await retry(
  File "/g/data/hh5/public/apps/miniconda3/envs/analysis3-24.04/lib/python3.10/site-packages/distributed/utils_comm.py", line 438, in retry
    return await coro()
  File "/g/data/hh5/public/apps/miniconda3/envs/analysis3-24.04/lib/python3.10/site-packages/distributed/core.py", line 1254, in send_recv_from_rpc
    return await send_recv(comm=comm, op=key, **kwargs)
  File "/g/data/hh5/public/apps/miniconda3/envs/analysis3-24.04/lib/python3.10/site-packages/distributed/core.py", line 1013, in send_recv
    response = await comm.read(deserializers=deserializers)
  File "/g/data/hh5/public/apps/miniconda3/envs/analysis3-24.04/lib/python3.10/site-packages/distributed/comm/tcp.py", line 236, in read
    convert_stream_closed_error(self, e)
  File "/g/data/hh5/public/apps/miniconda3/envs/analysis3-24.04/lib/python3.10/site-packages/distributed/comm/tcp.py", line 142, in convert_stream_closed_error
    raise CommClosedError(f"in {obj}: {exc}") from exc
distributed.comm.core.CommClosedError: in <TCP (closed) ConnectionPool.heartbeat_worker local=tcp://127.0.0.1:50510 remote=tcp://127.0.0.1:37367>: Stream is closed
2024-08-05 18:18:33,148 - distributed.worker - ERROR - Failed to communicate with scheduler during heartbeat.
Traceback (most recent call last):
  File "/g/data/hh5/public/apps/miniconda3/envs/analysis3-24.04/lib/python3.10/site-packages/distributed/comm/tcp.py", line 225, in read
    frames_nosplit_nbytes_bin = await stream.read_bytes(fmt_size)
tornado.iostream.StreamClosedError: Stream is closed

The above exception was the direct cause of the following exception:

Traceback (most recent call last):
  File "/g/data/hh5/public/apps/miniconda3/envs/analysis3-24.04/lib/python3.10/site-packages/distributed/worker.py", line 1250, in heartbeat
    response = await retry_operation(
  File "/g/data/hh5/public/apps/miniconda3/envs/analysis3-24.04/lib/python3.10/site-packages/distributed/utils_comm.py", line 459, in retry_operation
    return await retry(
  File "/g/data/hh5/public/apps/miniconda3/envs/analysis3-24.04/lib/python3.10/site-packages/distributed/utils_comm.py", line 438, in retry
    return await coro()
  File "/g/data/hh5/public/apps/miniconda3/envs/analysis3-24.04/lib/python3.10/site-packages/distributed/core.py", line 1254, in send_recv_from_rpc
    return await send_recv(comm=comm, op=key, **kwargs)
  File "/g/data/hh5/public/apps/miniconda3/envs/analysis3-24.04/lib/python3.10/site-packages/distributed/core.py", line 1013, in send_recv
    response = await comm.read(deserializers=deserializers)
  File "/g/data/hh5/public/apps/miniconda3/envs/analysis3-24.04/lib/python3.10/site-packages/distributed/comm/tcp.py", line 236, in read
    convert_stream_closed_error(self, e)
  File "/g/data/hh5/public/apps/miniconda3/envs/analysis3-24.04/lib/python3.10/site-packages/distributed/comm/tcp.py", line 142, in convert_stream_closed_error
    raise CommClosedError(f"in {obj}: {exc}") from exc
distributed.comm.core.CommClosedError: in <TCP (closed) ConnectionPool.heartbeat_worker local=tcp://127.0.0.1:50502 remote=tcp://127.0.0.1:37367>: Stream is closed
2024-08-05 18:18:33,155 - distributed.worker - ERROR - Failed to communicate with scheduler during heartbeat.
Traceback (most recent call last):
  File "/g/data/hh5/public/apps/miniconda3/envs/analysis3-24.04/lib/python3.10/site-packages/distributed/comm/tcp.py", line 225, in read
    frames_nosplit_nbytes_bin = await stream.read_bytes(fmt_size)
tornado.iostream.StreamClosedError: Stream is closed

The above exception was the direct cause of the following exception:

Traceback (most recent call last):
  File "/g/data/hh5/public/apps/miniconda3/envs/analysis3-24.04/lib/python3.10/site-packages/distributed/worker.py", line 1250, in heartbeat
    response = await retry_operation(
  File "/g/data/hh5/public/apps/miniconda3/envs/analysis3-24.04/lib/python3.10/site-packages/distributed/utils_comm.py", line 459, in retry_operation
    return await retry(
  File "/g/data/hh5/public/apps/miniconda3/envs/analysis3-24.04/lib/python3.10/site-packages/distributed/utils_comm.py", line 438, in retry
    return await coro()
  File "/g/data/hh5/public/apps/miniconda3/envs/analysis3-24.04/lib/python3.10/site-packages/distributed/core.py", line 1254, in send_recv_from_rpc
    return await send_recv(comm=comm, op=key, **kwargs)
  File "/g/data/hh5/public/apps/miniconda3/envs/analysis3-24.04/lib/python3.10/site-packages/distributed/core.py", line 1013, in send_recv
    response = await comm.read(deserializers=deserializers)
  File "/g/data/hh5/public/apps/miniconda3/envs/analysis3-24.04/lib/python3.10/site-packages/distributed/comm/tcp.py", line 236, in read
    convert_stream_closed_error(self, e)
  File "/g/data/hh5/public/apps/miniconda3/envs/analysis3-24.04/lib/python3.10/site-packages/distributed/comm/tcp.py", line 142, in convert_stream_closed_error
    raise CommClosedError(f"in {obj}: {exc}") from exc
distributed.comm.core.CommClosedError: in <TCP (closed) ConnectionPool.heartbeat_worker local=tcp://127.0.0.1:50556 remote=tcp://127.0.0.1:37367>: Stream is closed
2024-08-05 18:18:33,151 - distributed.worker - ERROR - Failed to communicate with scheduler during heartbeat.
Traceback (most recent call last):
  File "/g/data/hh5/public/apps/miniconda3/envs/analysis3-24.04/lib/python3.10/site-packages/distributed/comm/tcp.py", line 225, in read
    frames_nosplit_nbytes_bin = await stream.read_bytes(fmt_size)
tornado.iostream.StreamClosedError: Stream is closed

The above exception was the direct cause of the following exception:

Traceback (most recent call last):
  File "/g/data/hh5/public/apps/miniconda3/envs/analysis3-24.04/lib/python3.10/site-packages/distributed/worker.py", line 1250, in heartbeat
    response = await retry_operation(
  File "/g/data/hh5/public/apps/miniconda3/envs/analysis3-24.04/lib/python3.10/site-packages/distributed/utils_comm.py", line 459, in retry_operation
    return await retry(
  File "/g/data/hh5/public/apps/miniconda3/envs/analysis3-24.04/lib/python3.10/site-packages/distributed/utils_comm.py", line 438, in retry
    return await coro()
  File "/g/data/hh5/public/apps/miniconda3/envs/analysis3-24.04/lib/python3.10/site-packages/distributed/core.py", line 1254, in send_recv_from_rpc
    return await send_recv(comm=comm, op=key, **kwargs)
  File "/g/data/hh5/public/apps/miniconda3/envs/analysis3-24.04/lib/python3.10/site-packages/distributed/core.py", line 1013, in send_recv
    response = await comm.read(deserializers=deserializers)
  File "/g/data/hh5/public/apps/miniconda3/envs/analysis3-24.04/lib/python3.10/site-packages/distributed/comm/tcp.py", line 236, in read
    convert_stream_closed_error(self, e)
  File "/g/data/hh5/public/apps/miniconda3/envs/analysis3-24.04/lib/python3.10/site-packages/distributed/comm/tcp.py", line 142, in convert_stream_closed_error
    raise CommClosedError(f"in {obj}: {exc}") from exc
distributed.comm.core.CommClosedError: in <TCP (closed) ConnectionPool.heartbeat_worker local=tcp://127.0.0.1:50568 remote=tcp://127.0.0.1:37367>: Stream is closed
